2019-08-26 20:21:32,306 ERROR: Exception on / [GET] [in C:\home\Users\jhenck57\Documents\Anacondada\envs\django-env\lib\site-packages\flask\app.py:1891]
Traceback (most recent call last):
  File "C:\home\Users\jhenck57\Documents\Anacondada\envs\django-env\lib\site-packages\sqlalchemy\engine\base.py", line 1193, in _execute_context
    context)
  File "C:\home\Users\jhenck57\Documents\Anacondada\envs\django-env\lib\site-packages\sqlalchemy\engine\default.py", line 509, in do_execute
    cursor.execute(statement, parameters)
sqlite3.OperationalError: no such table: user

The above exception was the direct cause of the following exception:

Traceback (most recent call last):
  File "C:\home\Users\jhenck57\Documents\Anacondada\envs\django-env\lib\site-packages\flask\app.py", line 2446, in wsgi_app
    response = self.full_dispatch_request()
  File "C:\home\Users\jhenck57\Documents\Anacondada\envs\django-env\lib\site-packages\flask\app.py", line 1951, in full_dispatch_request
    rv = self.handle_user_exception(e)
  File "C:\home\Users\jhenck57\Documents\Anacondada\envs\django-env\lib\site-packages\flask\app.py", line 1820, in handle_user_exception
    reraise(exc_type, exc_value, tb)
  File "C:\home\Users\jhenck57\Documents\Anacondada\envs\django-env\lib\site-packages\flask\_compat.py", line 39, in reraise
    raise value
  File "C:\home\Users\jhenck57\Documents\Anacondada\envs\django-env\lib\site-packages\flask\app.py", line 1947, in full_dispatch_request
    rv = self.preprocess_request()
  File "C:\home\Users\jhenck57\Documents\Anacondada\envs\django-env\lib\site-packages\flask\app.py", line 2241, in preprocess_request
    rv = func()
  File "C:\Users\jhenck57\Documents\GitHub\flask-mega-tutorial-template\microblog\app\routes.py", line 18, in before_request
    if current_user.is_authenticated:
  File "C:\home\Users\jhenck57\Documents\Anacondada\envs\django-env\lib\site-packages\werkzeug\local.py", line 348, in __getattr__
    return getattr(self._get_current_object(), name)
  File "C:\home\Users\jhenck57\Documents\Anacondada\envs\django-env\lib\site-packages\werkzeug\local.py", line 307, in _get_current_object
    return self.__local()
  File "C:\home\Users\jhenck57\Documents\Anacondada\envs\django-env\lib\site-packages\flask_login\utils.py", line 26, in <lambda>
    current_user = LocalProxy(lambda: _get_user())
  File "C:\home\Users\jhenck57\Documents\Anacondada\envs\django-env\lib\site-packages\flask_login\utils.py", line 335, in _get_user
    current_app.login_manager._load_user()
  File "C:\home\Users\jhenck57\Documents\Anacondada\envs\django-env\lib\site-packages\flask_login\login_manager.py", line 359, in _load_user
    return self.reload_user()
  File "C:\home\Users\jhenck57\Documents\Anacondada\envs\django-env\lib\site-packages\flask_login\login_manager.py", line 321, in reload_user
    user = self.user_callback(user_id)
  File "C:\Users\jhenck57\Documents\GitHub\flask-mega-tutorial-template\microblog\app\models.py", line 81, in load_user
    return User.query.get(int(id))
  File "C:\home\Users\jhenck57\Documents\Anacondada\envs\django-env\lib\site-packages\sqlalchemy\orm\query.py", line 924, in get
    ident, loading.load_on_pk_identity)
  File "C:\home\Users\jhenck57\Documents\Anacondada\envs\django-env\lib\site-packages\sqlalchemy\orm\query.py", line 1007, in _get_impl
    return db_load_fn(self, primary_key_identity)
  File "C:\home\Users\jhenck57\Documents\Anacondada\envs\django-env\lib\site-packages\sqlalchemy\orm\loading.py", line 250, in load_on_pk_identity
    return q.one()
  File "C:\home\Users\jhenck57\Documents\Anacondada\envs\django-env\lib\site-packages\sqlalchemy\orm\query.py", line 2954, in one
    ret = self.one_or_none()
  File "C:\home\Users\jhenck57\Documents\Anacondada\envs\django-env\lib\site-packages\sqlalchemy\orm\query.py", line 2924, in one_or_none
    ret = list(self)
  File "C:\home\Users\jhenck57\Documents\Anacondada\envs\django-env\lib\site-packages\sqlalchemy\orm\query.py", line 2995, in __iter__
    return self._execute_and_instances(context)
  File "C:\home\Users\jhenck57\Documents\Anacondada\envs\django-env\lib\site-packages\sqlalchemy\orm\query.py", line 3018, in _execute_and_instances
    result = conn.execute(querycontext.statement, self._params)
  File "C:\home\Users\jhenck57\Documents\Anacondada\envs\django-env\lib\site-packages\sqlalchemy\engine\base.py", line 948, in execute
    return meth(self, multiparams, params)
  File "C:\home\Users\jhenck57\Documents\Anacondada\envs\django-env\lib\site-packages\sqlalchemy\sql\elements.py", line 269, in _execute_on_connection
    return connection._execute_clauseelement(self, multiparams, params)
  File "C:\home\Users\jhenck57\Documents\Anacondada\envs\django-env\lib\site-packages\sqlalchemy\engine\base.py", line 1060, in _execute_clauseelement
    compiled_sql, distilled_params
  File "C:\home\Users\jhenck57\Documents\Anacondada\envs\django-env\lib\site-packages\sqlalchemy\engine\base.py", line 1200, in _execute_context
    context)
  File "C:\home\Users\jhenck57\Documents\Anacondada\envs\django-env\lib\site-packages\sqlalchemy\engine\base.py", line 1413, in _handle_dbapi_exception
    exc_info
  File "C:\home\Users\jhenck57\Documents\Anacondada\envs\django-env\lib\site-packages\sqlalchemy\util\compat.py", line 265, in raise_from_cause
    reraise(type(exception), exception, tb=exc_tb, cause=cause)
  File "C:\home\Users\jhenck57\Documents\Anacondada\envs\django-env\lib\site-packages\sqlalchemy\util\compat.py", line 248, in reraise
    raise value.with_traceback(tb)
  File "C:\home\Users\jhenck57\Documents\Anacondada\envs\django-env\lib\site-packages\sqlalchemy\engine\base.py", line 1193, in _execute_context
    context)
  File "C:\home\Users\jhenck57\Documents\Anacondada\envs\django-env\lib\site-packages\sqlalchemy\engine\default.py", line 509, in do_execute
    cursor.execute(statement, parameters)
sqlalchemy.exc.OperationalError: (sqlite3.OperationalError) no such table: user [SQL: 'SELECT user.id AS user_id, user.username AS user_username, user.email AS user_email, user.password_hash AS user_password_hash, user.about_me AS user_about_me, user.last_seen AS user_last_seen \nFROM user \nWHERE user.id = ?'] [parameters: (3,)] (Background on this error at: http://sqlalche.me/e/e3q8)
